Workbook

Sheet All_India_Index_Upto_April23 (1
A1: Sector | B1: Year | C1: Month | D1: Cereals and products | E1: Meat and fish | F1: Egg | G1: Milk and products | H1: Oils and fats | I1: Fruits | J1: Vegetables | K1: Pulses and products | L1: Sugar and Confectionery | M1: Spices | N1: Non-alcoholic beverages | O1: Prepared meals, snacks, sweets etc. | P1: Food and beverages | Q1: Pan, tobacco and intoxicants | R1: Clothing | S1: Footwear | T1: Clothing and footwear | U1: Housing | V1: Fuel and light | W1: Household goods and services | X1: Health | Y1: Transport and communication | Z1: Recreation and amusement | AA1: Education | AB1: Personal care and effects | AC1: Miscellaneous | AD1: General index
A2: Rural | B2: 2013 | C2: January | D2: 107.5 | E2: 106.3 | F2: 108.1 | G2: 104.9 | H2: 106.1 | I2: 103.9 | J2: 101.9 | K2: 106.1 | L2: 106.8 | M2: 103.1 | N2: 104.8 | O2: 106.7 | P2: 105.5 | Q2: 105.1 | R2: 106.5 | S2: 105.8 | T2: 106.4 | U2: NA | V2: 105.5 | W2: 104.8 | X2: 104 | Y2: 103.3 | Z2: 103.4 | AA2: 103.8 | AB2: 104.7 | AC2: 104 | AD2: 105.1
A3: Urban | B3: 2013 | C3: January | D3: 110.5 | E3: 109.1 | F3: 113 | G3: 103.6 | H3: 103.4 | I3: 102.3 | J3: 102.9 | K3: 105.8 | L3: 105.1 | M3: 101.8 | N3: 105.1 | O3: 107.9 | P3: 105.9 | Q3: 105.2 | R3: 105.9 | S3: 105 | T3: 105.8 | U3: 100.3 | V3: 105.4 | W3: 104.8 | X3: 104.1 | Y3: 103.2 | Z3: 102.9 | AA3: 103.5 | AB3: 104.3 | AC3: 103.7 | AD3: 104
A4: Rural+Urban | B4: 2013 | C4: January | D4: 108.4 | E4: 107.3 | F4: 110 | G4: 104.4 | H4: 105.1 | I4: 103.2 | J4: 102.2 | K4: 106 | L4: 106.2 | M4: 102.7 | N4: 104.9 | O4: 107.3 | P4: 105.6 | Q4: 105.1 | R4: 106.3 | S4: 105.5 | T4: 106.2 | U4: 100.3 | V4: 105.5 | W4: 104.8 | X4: 104 | Y4: 103.2 | Z4: 103.1 | AA4: 103.6 | AB4: 104.5 | AC4: 103.9 | AD4: 104.6
A5: Rural | B5: 2013 | C5: February | D5: 109.2 | E5: 108.7 | F5: 110.2 | G5: 105.4 | H5: 106.7 | I5: 104 | J5: 102.4 | K5: 105.9 | L5: 105.7 | M5: 103.1 | N5: 105.1 | O5: 107.7 | P5: 106.3 | Q5: 105.6 | R5: 107.1 | S5: 106.3 | T5: 107 | U5: NA | V5: 106.2 | W5: 105.2 | X5: 104.4 | Y5: 103.9 | Z5: 104 | AA5: 104.1 | AB5: 104.6 | AC5: 104.4 | AD5: 105.8
A6: Urban | B6: 2013 | C6: February | D6: 112.9 | E6: 112.9 | F6: 116.9 | G6: 104 | H6: 103.5 | I6: 103.1 | J6: 104.9 | K6: 104.1 | L6: 103.8 | M6: 102.3 | N6: 106 | O6: 109 | P6: 107.2 | Q6: 106 | R6: 106.6 | S6: 105.5 | T6: 106.4 | U6: 100.4 | V6: 105.7 | W6: 105.2 | X6: 104.7 | Y6: 104.4 | Z6: 103.3 | AA6: 103.7 | AB6: 104.3 | AC6: 104.3 | AD6: 104.7
A7: Rural+Urban | B7: 2013 | C7: February | D7: 110.4 | E7: 110.2 | F7: 112.8 | G7: 104.9 | H7: 105.5 | I7: 103.6 | J7: 103.2 | K7: 105.3 | L7: 105.1 | M7: 102.8 | N7: 105.5 | O7: 108.3 | P7: 106.6 | Q7: 105.7 | R7: 106.9 | S7: 106 | T7: 106.8 | U7: 100.4 | V7: 106 | W7: 105.2 | X7: 104.5 | Y7: 104.2 | Z7: 103.6 | AA7: 103.9 | AB7: 104.5 | AC7: 104.4 | AD7: 105.3
A8: Rural | B8: 2013 | C8: March | D8: 110.2 | E8: 108.8 | F8: 109.9 | G8: 105.6 | H8: 106.2 | I8: 105.7 | J8: 101.4 | K8: 105.7 | L8: 105 | M8: 103.3 | N8: 105.6 | O8: 108.2 | P8: 106.6 | Q8: 106.5 | R8: 107.6 | S8: 106.8 | T8: 107.5 | U8: NA | V8: 106.1 | W8: 105.6 | X8: 104.7 | Y8: 104.6 | Z8: 104 | AA8: 104.3 | AB8: 104.3 | AC8: 104.6 | AD8: 106
A9: Urban | B9: 2013 | C9: March | D9: 113.9 | E9: 111.4 | F9: 113.2 | G9: 104.3 | H9: 102.7 | I9: 104.9 | J9: 103.8 | K9: 103.5 | L9: 102.6 | M9: 102.4 | N9: 107 | O9: 109.8 | P9: 107.3 | Q9: 106.8 | R9: 107.2 | S9: 106 | T9: 107 | U9: 100.4 | V9: 106 | W9: 105.7 | X9: 105.2 | Y9: 105.5 | Z9: 103.5 | AA9: 103.8 | AB9: 104.2 | AC9: 104.9 | AD9: 105
A10: Rural+Urban | B10: 2013 | C10: March | D10: 111.4 | E10: 109.7 | F10: 111.2 | G10: 105.1 | H10: 104.9 | I10: 105.3 | J10: 102.2 | K10: 105 | L10: 104.2 | M10: 103 | N10: 106.2 | O10: 108.9 | P10: 106.9 | Q10: 106.6 | R10: 107.4 | S10: 106.5 | T10: 107.3 | U10: 100.4 | V10: 106.1 | W10: 105.6 | X10: 104.9 | Y10: 105.1 | Z10: 103.7 | AA10: 104 | AB10: 104.3 | AC10: 104.7 | AD10: 105.5
A11: Rural | B11: 2013 | C11: April | D11: 110.2 | E11: 109.5 | F11: 106.9 | G11: 106.3 | H11: 105.7 | I11: 108.3 | J11: 103.4 | K11: 105.7 | L11: 104.2 | M11: 103.2 | N11: 106.5 | O11: 108.8 | P11: 107.1 | Q11: 107.1 | R11: 108.1 | S11: 107.4 | T11: 108 | U11: NA | V11: 106.5 | W11: 106.1 | X11: 105.1 | Y11: 104.4 | Z11: 104.5 | AA11: 104.8 | AB11: 102.7 | AC11: 104.6 | AD11: 106.4
A12: Urban | B12: 2013 | C12: April | D12: 114.6 | E12: 113.4 | F12: 106 | G12: 104.7 | H12: 102.1 | I12: 109.5 | J12: 109.7 | K12: 104.6 | L12: 102 | M12: 103.5 | N12: 108.2 | O12: 110.6 | P12: 108.8 | Q12: 108.5 | R12: 107.9 | S12: 106.4 | T12: 107.7 | U12: 100.5 | V12: 106.4 | W12: 106.5 | X12: 105.7 | Y12: 105 | Z12: 104 | AA12: 105.2 | AB12: 103.2 | AC12: 105.1 | AD12: 105.7
A13: Rural+Urban | B13: 2013 | C13: April | D13: 111.6 | E13: 110.9 | F13: 106.6 | G13: 105.7 | H13: 104.4 | I13: 108.9 | J13: 105.5 | K13: 105.3 | L13: 103.5 | M13: 103.3 | N13: 107.2 | O13: 109.6 | P13: 107.7 | Q13: 107.5 | R13: 108 | S13: 107 | T13: 107.9 | U13: 100.5 | V13: 106.5 | W13: 106.3 | X13: 105.3 | Y13: 104.7 | Z13: 104.2 | AA13: 105 | AB13: 102.9 | AC13: 104.8 | AD13: 106.1
... A259: Rural+Urban | B259: 2020 | C259: March | D259: 145.1 | E259: 167 | F259: 148.1 | G259: 151.5 | H259: 131.2 | I259: 142.5 | J259: 157.3 | K259: 141.1 | L259: 113.2 | M259: 153.2 | N259: 136.7 | O259: 159.6 | P259: 148.9 | Q259: 171.2 | R259: 151.2 | S259: 141.9 | T259: 149.8 | U259: 154.5 | V259: 148.9 | W259: 146.4 | X259: 152.3 | Y259: 129.9 | Z259: 143.7 | AA259: 156.1 | AB259: 145.2 | AC259: 143.8 | AD259: 148.6
A260: Rural | B260: 2020 | C260: April | D260: 147.2 | F260: 146.9 | G260: 155.6 | H260: 137.1 | I260: 147.3 | J260: 162.7 | K260: 150.2 | L260: 119.8 | M260: 158.7 | N260: 139.2 | P260: 150.1 | U260: NA | V260: 148.4 | X260: 154.3
A261: Urban | B261: 2020 | C261: April | D261: 151.8 | F261: 151.9 | G261: 155.5 | H261: 131.6 | I261: 152.9 | J261: 180 | K261: 150.8 | L261: 121.2 | M261: 154 | N261: 133.5 | P261: 153.5 | U261: 155.6 | V261: 137.1 | X261: 144.8
A262: Rural+Urban | B262: 2020 | C262: April | D262: 148.7 | F262: 148.8 | G262: 155.6 | H262: 135.1 | I262: 149.9 | J262: 168.6 | K262: 150.4 | L262: 120.3 | M262: 157.1 | N262: 136.8 | P262: 151.4 | U262: 155.6 | V262: 144.1 | X262: 150.7
A263: Rural | B263: 2020 | C263: May | U263: NA
A264: Urban | B264: 2020 | C264: May | U264: NA
A265: Rural+Urban | B265: 2020 | C265: May | U265: NA
A266: Rural | B266: 2020 | C266: June | D266: 148.2 | E266: 190.3 | F266: 149.4 | G266: 153.3 | H266: 138.2 | I266: 143.2 | J266: 148.9 | K266: 150.3 | L266: 113.2 | M266: 159.8 | N266: 142.1 | O266: 161.8 | P266: 152.3 | Q266: 182.4 | R266: 154.7 | S266: 150 | T266: 154.1 | U266: NA | V266: 144.9 | W266: 151.7 | X266: 158.2 | Y266: 141.4 | Z266: 153.2 | AA266: 161.8 | AB266: 151.2 | AC266: 151.7 | AD266: 152.7
A267: Urban | B267: 2020 | C267: June | D267: 152.7 | E267: 197 | F267: 154.6 | G267: 153.4 | H267: 132.9 | I267: 151.8 | J267: 171.2 | K267: 152 | L267: 116.3 | M267: 158.8 | N267: 135.6 | O267: 161.7 | P267: 157 | Q267: 186.7 | R267: 149.1 | S267: 136.6 | T267: 147.2 | U267: 154.7 | V267: 137.1 | W267: 140.4 | X267: 148.1 | Y267: 129.3 | Z267: 144.5 | AA267: 152.5 | AB267: 152.2 | AC267: 142 | AD267: 150.8
A268: Rural+Urban | B268: 2020 | C268: June | D268: 149.6 | E268: 192.7 | F268: 151.4 | G268: 153.3 | H268: 136.3 | I268: 147.2 | J268: 156.5 | K268: 150.9 | L268: 114.2 | M268: 159.5 | N268: 139.4 | O268: 161.8 | P268: 154 | Q268: 183.5 | R268: 152.5 | S268: 144.4 | T268: 151.4 | U268: 154.7 | V268: 141.9 | W268: 146.4 | X268: 154.4 | Y268: 135 | Z268: 148.3 | AA268: 156.4 | AB268: 151.6 | AC268: 147 | AD268: 151.8
A269: Rural | B269: 2020 | C269: July | D269: 148.2 | E269: 190.3 | F269: 149.4 | G269: 153.3 | H269: 138.2 | I269: 143.2 | J269: 148.9 | K269: 150.3 | L269: 113.2 | M269: 159.8 | N269: 142.1 | O269: 161.8 | P269: 152.3 | Q269: 182.4 | R269: 154.7 | S269: 150 | T269: 154.1 | U269: NA | V269: 144.9 | W269: 151.7 | X269: 158.2 | Y269: 141.4 | Z269: 153.2 | AA269: 161.8 | AB269: 151.2 | AC269: 151.7 | AD269: 152.7
A270: Urban | B270: 2020 | C270: July | D270: 152.7 | E270: 197 | F270: 154.6 | G270: 153.4 | H270: 132.9 | I270: 151.8 | J270: 171.2 | K270: 152 | L270: 116.3 | M270: 158.8 | N270: 135.6 | O270: 161.7 | P270: 157 | Q270: 186.7 | R270: 149.1 | S270: 136.6 | T270: 147.2 | U270: 154.7 | V270: 137.1 | W270: 140.4 | X270: 148.1 | Y270: 129.3 | Z270: 144.5 | AA270: 152.5 | AB270: 152.2 | AC270: 142 | AD270: 150.8
A271: Rural+Urban | B271: 2020 | C271: July | D271: 149.6 | E271: 192.7 | F271: 151.4 | G271: 153.3 | H271: 136.3 | I271: 147.2 | J271: 156.5 | K271: 150.9 | L271: 114.2 | M271: 159.5 | N271: 139.4 | O271: 161.8 | P271: 154 | Q271: 183.5 | R271: 152.5 | S271: 144.4 | T271: 151.4 | U271: 154.7 | V271: 141.9 | W271: 146.4 | X271: 154.4 | Y271: 135 | Z271: 148.3 | AA271: 156.4 | AB271: 151.6 | AC271: 147 | AD271: 151.8
A272: Rural | B272: 2020 | C272: August | D272: 147.6 | E272: 187.2 | F272: 148.4 | G272: 153.3 | H272: 139.8 | I272: 146.9 | J272: 171 | K272: 149.9 | L272: 114.2 | M272: 160 | N272: 143.5 | O272: 161.5 | P272: 155.3 | Q272: 180.9 | R272: 155.1 | S272: 149.3 | T272: 154.3 | U272: NA | V272: 145.8 | W272: 151.9 | X272: 158.8 | Y272: 143.6 | Z272: 152.2 | AA272: 162.7 | AB272: 153.6 | AC272: 153 | AD272: 154.7
A273: Urban | B273: 2020 | C273: August | D273: 151.6 | E273: 197.8 | F273: 154.5 | G273: 153.4 | H273: 133.4 | I273: 154.5 | J273: 191.9 | K273: 151.3 | L273: 116.8 | M273: 160 | N273: 136.5 | O273: 163.3 | P273: 159.9 | Q273: 187.2 | R273: 150 | S273: 135.2 | T273: 147.8 | U273: 155.5 | V273: 138.3 | W273: 144.5 | X273: 148.7 | Y273: 133.9 | Z273: 141.2 | AA273: 155.5 | AB273: 155.2 | AC273: 144.8 | AD273: 152.9
A274: Rural+Urban | B274: 2020 | C274: August | D274: 148.9 | E274: 190.9 | F274: 150.8 | G274: 153.3 | H274: 137.4 | I274: 150.4 | J274: 178.1 | K274: 150.4 | L274: 115.1 | M274: 160 | N274: 140.6 | O274: 162.3 | P274: 157 | Q274: 182.6 | R274: 153.1 | S274: 143.4 | T274: 151.7 | U274: 155.5 | V274: 143 | W274: 148.4 | X274: 155 | Y274: 138.5 | Z274: 146 | AA274: 158.5 | AB274: 154.3 | AC274: 149 | AD274: 153.9
A275: Rural | B275: 2020 | C275: September | D275: 146.9 | E275: 183.9 | F275: 149.5 | G275: 153.4 | H275: 140.4 | I275: 147 | J275: 178.8 | K275: 149.3 | L275: 115.1 | M275: 160 | N275: 145.4 | O275: 161.6 | P275: 156.1 | Q275: 182.9 | R275: 155.4 | S275: 149.9 | T275: 154.6 | U275: NA | V275: 146.4 | W275: 151.6 | X275: 159.1 | Y275: 144.6 | Z275: 152.8 | AA275: 161.1 | AB275: 157.4 | AC275: 153.7 | AD275: 155.4
A276: Urban | B276: 2020 | C276: September | D276: 151.5 | E276: 193.1 | F276: 157.3 | G276: 153.9 | H276: 134.4 | I276: 155.4 | J276: 202 | K276: 150.8 | L276: 118.9 | M276: 160.9 | N276: 137.7 | O276: 164.4 | P276: 161.3 | Q276: 188.7 | R276: 150.2 | S276: 136.3 | T276: 148.1 | U276: 156.3 | V276: 137.2 | W276: 145.4 | X276: 150 | Y276: 135.1 | Z276: 141.8 | AA276: 154.9 | AB276: 159.8 | AC276: 146 | AD276: 154
A277: Rural+Urban | B277: 2020 | C277: September | D277: 148.4 | E277: 187.1 | F277: 152.5 | G277: 153.6 | H277: 138.2 | I277: 150.9 | J277: 186.7 | K277: 149.8 | L277: 116.4 | M277: 160.3 | N277: 142.2 | O277: 162.9 | P277: 158 | Q277: 184.4 | R277: 153.4 | S277: 144.3 | T277: 152 | U277: 156.3 | V277: 142.9 | W277: 148.7 | X277: 155.6 | Y277: 139.6 | Z277: 146.6 | AA277: 157.5 | AB277: 158.4 | AC277: 150 | AD277: 154.7
... A373: Rural+Urban | B373: 2023 | C373: May | D373: 173.7 | E373: 214.3 | F373: 173.2 | G373: 179.5 | H373: 170 | I373: 172.2 | J373: 161 | K373: 175.6 | L373: 122.7 | M373: 218 | N373: 173.4 | O373: 194.2 | P373: 179.1 | Q373: 201 | R373: 187.3 | S373: 179.7 | T373: 186.2 | U373: 175.6 | V373: 182.8 | W373: 175.2 | X373: 185.7 | Y373: 164.8 | Z373: 171.2 | AA373: 177.1 | AB373: 185.2 | AC373: 175.7 | AD373: 179.1

Sheet Que2 Insights
D3: Y-o-Y Analysis for Inflamation in the Categories starting from Year 2017
C28: Insights | P28: Insights
C29: Year 2020 and Year 2021 has highest inflamation | P29: Year 2022 has the highest inflamation
C30: We can see there is a steady rise in inflamation in the year 2019 | P30: There is a big spike in inflamation in the year 2021
C31: In 2022 inflamation starts to decline
B55: Insights | P55: Insights
B56: Year 2020 and Year 2021 has spike due to Covid-19 period | P56: Year 2021 has the highest inflamation rate
B57: Year 2021 has the highest inflamation in Healthcare | P57: From year 2022 there is a decrease in inflamation
B82: Insights
B83: Year 2022 has the highest inflamation rate
B84: From late Year 2019 there is a steady increase in inflamation
B85: Year 2023 there is a steady decline in inflamation

Sheet Que 4 Insights M-o-M
D2: Insights for M-o-M Analysis for Inflamation due to Covid-19 on various categories
C26: Insights | P26: Insights
C27: The Year 2020 has high Inflamation as it is Covid-19 period. It may be due to panic buying, Supply chain disruptions. | P27: In the Year 2020 early there was a dip in Essential services due to Lockdown affecting Travel and education sectors largely.
C28: The period from 2017 to 2020 early is considered as Pre-covid inflamation is stable. | P28: Year 2021 has highest Inflamation it can be seen due to reopening after Lockdown Period and increase in demands and services.
C29: The period from Year 2021 to 2023 can be considered Post-Covid the inflamation is stable as there are normal spike. | P29: The Post-Covid period we can see the essential services demand has returned to stable nut the prices are high as compared to Pre-Covid period.
C30: The supply chain was largely affected during covid period due to demand
C57: Insights | P57: Insights
C58: Healthcare has highest inflamation in the year 2020 due to Covid-19. | P58: Year 2020 has the highest Inflamation due to Covid-19. As in general the demands were high for all categories.
C59: In Pre-covid there was a spike in the year 2018. | P59: Post-Covid there are spikes due to economics recovery and the rise in cost in all sectors.
C60: The inflamation was stable in Post-Covid but high as compared to Pre-Covid

Sheet Que 4 Y-o-Y Insights
C3: Y-o-Y Analysis for Covid-19 Inflamation on various categories
P27: Insights
B28: Insights | P28: Year 2022 has the highest inflamation due to Covid.
B29: Pre-Covid from year 2017 to early 2029 the food prices were stable due to stable market condition and balanced supply chain. | P29: Pre-Covid the inflamation was steady as the supply chain was stable.
B30: Covid preiod from early 2020 to 2021 the prices were high due to panic buying, transport restrictions which affected supply chain. | P30: During Post-Covid Period the prices went up due to increased demands,recovery of ecomonics activities.
B31: From Year 2022 to 2023 it can be depicted market is stable due to recovery of supply chain, Increased food production. | P31: But it can also be seen that from the end of year 2022 the inflamation starts to drop.
B32: Highest Inflamation can be seen in the year 2020.
B57: Insights | P57: Insights
B58: Year 2021 can be seen as highest inflamation in helathcare. | P58: Pre-Covid inflamation can be seen stable due to stable demand and economic conditions.
B59: Spike in inflamation can be seen during Covid period from year 2020 due to increase in medical demand during Covid. | P59: Year 2020 can be considered Covid period and has spike in inflamtion due to covid restictions and disruptions in supply chain.
B60: Healthcare inflamation has remained high from the covid period. | P60: Highest inflamation can be seen in the year 2021 during covid-19 period.
P61: Year 2023 inflamation can be seen as declining

Sheet Que5 Insight MOM
F2: Insight for Month-On-Month Analysis for Crude Oil
C24: Insights
C25: Year 2021 has the highest Inflamation in the food sector. | P25: Insights
C26: Year 2022 has stable inflamation but the prices trend increase in 2023. | P26: Highest Inflamation Occurs in the year 2022 due to Covid-19 due to major global market disruptions.
P27: Year 2021 can be observed as the prices are not stable.
P28: Year 2023 can be observed as low inflamtion and the inflamation is stable.
C54: Insights | P54: Insights
C55: Highest Inflamation occurred in the year 2022 in the transportation and communication sector. | P55: In General CPI highest inflamation occurs in the year 2021.
C56: Whereas the year mid 2022 to 2023 shows stable and low inflamation in the transport and communication sector. | P56: The inflamation is fluctuating in the year 2021 but stable in 2022 as compared to 2021.
P57: Year 2023 has low and stable inflamation as compared to years 2021 and 2022.
C83: Insights
C84: Highest Inflamation in Crude Oil occrus in Year 2022.
C85: Overall crude oil inflamation is very volatile
C111: Insights | Q111: Insights
C112: Crude Oil Prices are more volatile as compared to Fule and Light Prices. | Q112: Crude Oil is very volatile ans Transport and communication is stable as compared to it.
C113: Changes in Crude Oil partially affect the inflamation of the Fuel and Light. | Q113: Crude Oil partially Influence the transport and communication cost.

Sheet Que 5 Insight YOY
G2: Insights for Year-On-Year Analysis for Crude Oil
B23: Insights | O23: Insights
B24: Highest Inflamation in Food and beverages occurred in the year 2021. | O24: Highest Inflamation occurs in the year 2021 in the Fuel and Light sector.
B25: The food inflamation significantly drop towards the end of 2021 and the inflamation is stable. | O25: The Prices of Fuel and Light are relatively high in 2022 but are stable as there are not much fluctuations in prices.
O26: Year 2023 the inflamation decreases.
B53: Insights | O53: Insights
B54: Highest Inflamation in Transport and communication can be seen in the Year 2021 and in the month of May. | O54: Highest Inflamation For General CPI occurs in the year 2022 for the month of April.
B55: The inflamation gradually starts declining after 2021. | O55: Inflamation for the Year 2022 is highas compared to 2021.
B56: Lowest inflamation can be seen in year 2023. | O56: Inflamation gradually is declining for the year 2023.
B82: Insights | O82: Insights
B83: Crude Oil has the highest inflamation in the year 2021 in the month of April. | O83: The Crude Oil inflamation is very Volatile as compared to the General CPI.
B84: From the late 2021 the inflamation is steadily declining. | O84: Large spikes in the Crude oil may partially influence the General CPI as it consists of multiple categories.
B112: Insights | O112: Insights
B113: Fuel and Light Inflamation is comparatively stable as compared to the Crude Oil inflamation. | O113: Inflamation for the Crude oil is very volatile as compared to the Transport and communication prices.
B114: Changes in Crude Oil affect the Fuel and Light category but has a small impact. | O114: Changes in the Crude Oil may affect the transportation cost.

Sheet Clean
A1: Sector | B1: Year | C1: Month | D1: Index | E1: Sector and Year | F1: Housing Clean | G1: Cereals and products | H1: Meat and fish | I1: Egg | J1: Milk and products | K1: Oils and fats | L1: Fruits | M1: Vegetables | N1: Pulses and products | O1: Sugar and Confectionery | P1: Spices | Q1: Non-alcoholic beverages | R1: Prepared meals, snacks, sweets etc. | S1: Food and beverages | T1: Pan, tobacco and intoxicants | U1: Clothing | V1: Footwear | W1: Clothing and footwear | X1: Housing | Y1: Fuel and light | Z1: Household goods and services | AA1: Health | AB1: Transport and communication | AC1: Recreation and amusement | AD1: Education | AE1: Personal care and effects | AF1: Miscellaneous | AG1: General index
A2: Rural | B2: 2013 | C2: January | D2: =VLOOKUP(All_India_Index_Upto_April23__1___13[[#This Row],[Month]],Lookups!$E$1:$F$13,2,0) -> 1 | E2: Rural 2013 January | F2: 100.3 | G2: 107.5 | H2: 106.3 | I2: 108.1 | J2: 104.9 | K2: 106.1 | L2: 103.9 | M2: 101.9 | N2: 106.1 | O2: 106.8 | P2: 103.1 | Q2: 104.8 | R2: 106.7 | S2: 105.5 | T2: 105.1 | U2: 106.5 | V2: 105.8 | W2: 106.4 | X2: NA | Y2: 105.5 | Z2: 104.8 | AA2: 104 | AB2: 103.3 | AC2: 103.4 | AD2: 103.8 | AE2: 104.7 | AF2: 104 | AG2: 105.1
A3: Urban | B3: 2013 | C3: January | D3: =VLOOKUP(All_India_Index_Upto_April23__1___13[[#This Row],[Month]],Lookups!$E$1:$F$13,2,0) -> 1 | E3: Urban 2013 January | F3: 100.3 | G3: 110.5 | H3: 109.1 | I3: 113 | J3: 103.6 | K3: 103.4 | L3: 102.3 | M3: 102.9 | N3: 105.8 | O3: 105.1 | P3: 101.8 | Q3: 105.1 | R3: 107.9 | S3: 105.9 | T3: 105.2 | U3: 105.9 | V3: 105 | W3: 105.8 | X3: 100.3 | Y3: 105.4 | Z3: 104.8 | AA3: 104.1 | AB3: 103.2 | AC3: 102.9 | AD3: 103.5 | AE3: 104.3 | AF3: 103.7 | AG3: 104
A4: Rural+Urban | B4: 2013 | C4: January | D4: =VLOOKUP(All_India_Index_Upto_April23__1___13[[#This Row],[Month]],Lookups!$E$1:$F$13,2,0) -> 1 | E4: Rural+Urban 2013 January | F4: 100.3 | G4: 108.4 | H4: 107.3 | I4: 110 | J4: 104.4 | K4: 105.1 | L4: 103.2 | M4: 102.2 | N4: 106 | O4: 106.2 | P4: 102.7 | Q4: 104.9 | R4: 107.3 | S4: 105.6 | T4: 105.1 | U4: 106.3 | V4: 105.5 | W4: 106.2 | X4: 100.3 | Y4: 105.5 | Z4: 104.8 | AA4: 104 | AB4: 103.2 | AC4: 103.1 | AD4: 103.6 | AE4: 104.5 | AF4: 103.9 | AG4: 104.6
A5: Rural | B5: 2013 | C5: February | D5: =VLOOKUP(All_India_Index_Upto_April23__1___13[[#This Row],[Month]],Lookups!$E$1:$F$13,2,0) -> 2 | E5: Rural 2013 February | F5: 100.4 | G5: 109.2 | H5: 108.7 | I5: 110.2 | J5: 105.4 | K5: 106.7 | L5: 104 | M5: 102.4 | N5: 105.9 | O5: 105.7 | P5: 103.1 | Q5: 105.1 | R5: 107.7 | S5: 106.3 | T5: 105.6 | U5: 107.1 | V5: 106.3 | W5: 107 | X5: NA | Y5: 106.2 | Z5: 105.2 | AA5: 104.4 | AB5: 103.9 | AC5: 104 | AD5: 104.1 | AE5: 104.6 | AF5: 104.4 | AG5: 105.8
A6: Urban | B6: 2013 | C6: February | D6: =VLOOKUP(All_India_Index_Upto_April23__1___13[[#This Row],[Month]],Lookups!$E$1:$F$13,2,0) -> 2 | E6: Urban 2013 February | F6: 100.4 | G6: 112.9 | H6: 112.9 | I6: 116.9 | J6: 104 | K6: 103.5 | L6: 103.1 | M6: 104.9 | N6: 104.1 | O6: 103.8 | P6: 102.3 | Q6: 106 | R6: 109 | S6: 107.2 | T6: 106 | U6: 106.6 | V6: 105.5 | W6: 106.4 | X6: 100.4 | Y6: 105.7 | Z6: 105.2 | AA6: 104.7 | AB6: 104.4 | AC6: 103.3 | AD6: 103.7 | AE6: 104.3 | AF6: 104.3 | AG6: 104.7
A7: Rural+Urban | B7: 2013 | C7: February | D7: =VLOOKUP(All_India_Index_Upto_April23__1___13[[#This Row],[Month]],Lookups!$E$1:$F$13,2,0) -> 2 | E7: Rural+Urban 2013 February | F7: 100.4 | G7: 110.4 | H7: 110.2 | I7: 112.8 | J7: 104.9 | K7: 105.5 | L7: 103.6 | M7: 103.2 | N7: 105.3 | O7: 105.1 | P7: 102.8 | Q7: 105.5 | R7: 108.3 | S7: 106.6 | T7: 105.7 | U7: 106.9 | V7: 106 | W7: 106.8 | X7: 100.4 | Y7: 106 | Z7: 105.2 | AA7: 104.5 | AB7: 104.2 | AC7: 103.6 | AD7: 103.9 | AE7: 104.5 | AF7: 104.4 | AG7: 105.3
A8: Rural | B8: 2013 | C8: March | D8: =VLOOKUP(All_India_Index_Upto_April23__1___13[[#This Row],[Month]],Lookups!$E$1:$F$13,2,0) -> 3 | E8: Rural 2013 March | F8: 100.4 | G8: 110.2 | H8: 108.8 | I8: 109.9 | J8: 105.6 | K8: 106.2 | L8: 105.7 | M8: 101.4 | N8: 105.7 | O8: 105 | P8: 103.3 | Q8: 105.6 | R8: 108.2 | S8: 106.6 | T8: 106.5 | U8: 107.6 | V8: 106.8 | W8: 107.5 | X8: NA | Y8: 106.1 | Z8: 105.6 | AA8: 104.7 | AB8: 104.6 | AC8: 104 | AD8: 104.3 | AE8: 104.3 | AF8: 104.6 | AG8: 106
A9: Urban | B9: 2013 | C9: March | D9: =VLOOKUP(All_India_Index_Upto_April23__1___13[[#This Row],[Month]],Lookups!$E$1:$F$13,2,0) -> 3 | E9: Urban 2013 March | F9: 100.4 | G9: 113.9 | H9: 111.4 | I9: 113.2 | J9: 104.3 | K9: 102.7 | L9: 104.9 | M9: 103.8 | N9: 103.5 | O9: 102.6 | P9: 102.4 | Q9: 107 | R9: 109.8 | S9: 107.3 | T9: 106.8 | U9: 107.2 | V9: 106 | W9: 107 | X9: 100.4 | Y9: 106 | Z9: 105.7 | AA9: 105.2 | AB9: 105.5 | AC9: 103.5 | AD9: 103.8 | AE9: 104.2 | AF9: 104.9 | AG9: 105
A10: Rural+Urban | B10: 2013 | C10: March | D10: =VLOOKUP(All_India_Index_Upto_April23__1___13[[#This Row],[Month]],Lookups!$E$1:$F$13,2,0) -> 3 | E10: Rural+Urban 2013 March | F10: 100.4 | G10: 111.4 | H10: 109.7 | I10: 111.2 | J10: 105.1 | K10: 104.9 | L10: 105.3 | M10: 102.2 | N10: 105 | O10: 104.2 | P10: 103 | Q10: 106.2 | R10: 108.9 | S10: 106.9 | T10: 106.6 | U10: 107.4 | V10: 106.5 | W10: 107.3 | X10: 100.4 | Y10: 106.1 | Z10: 105.6 | AA10: 104.9 | AB10: 105.1 | AC10: 103.7 | AD10: 104 | AE10: 104.3 | AF10: 104.7 | AG10: 105.5
A11: Rural | B11: 2013 | C11: April | D11: =VLOOKUP(All_India_Index_Upto_April23__1___13[[#This Row],[Month]],Lookups!$E$1:$F$13,2,0) -> 4 | E11: Rural 2013 April | F11: 100.5 | G11: 110.2 | H11: 109.5 | I11: 106.9 | J11: 106.3 | K11: 105.7 | L11: 108.3 | M11: 103.4 | N11: 105.7 | O11: 104.2 | P11: 103.2 | Q11: 106.5 | R11: 108.8 | S11: 107.1 | T11: 107.1 | U11: 108.1 | V11: 107.4 | W11: 108 | X11: NA | Y11: 106.5 | Z11: 106.1 | AA11: 105.1 | AB11: 104.4 | AC11: 104.5 | AD11: 104.8 | AE11: 102.7 | AF11: 104.6 | AG11: 106.4
A12: Urban | B12: 2013 | C12: April | D12: =VLOOKUP(All_India_Index_Upto_April23__1___13[[#This Row],[Month]],Lookups!$E$1:$F$13,2,0) -> 4 | E12: Urban 2013 April | F12: 100.5 | G12: 114.6 | H12: 113.4 | I12: 106 | J12: 104.7 | K12: 102.1 | L12: 109.5 | M12: 109.7 | N12: 104.6 | O12: 102 | P12: 103.5 | Q12: 108.2 | R12: 110.6 | S12: 108.8 | T12: 108.5 | U12: 107.9 | V12: 106.4 | W12: 107.7 | X12: 100.5 | Y12: 106.4 | Z12: 106.5 | AA12: 105.7 | AB12: 105 | AC12: 104 | AD12: 105.2 | AE12: 103.2 | AF12: 105.1 | AG12: 105.7
A13: Rural+Urban | B13: 2013 | C13: April | D13: =VLOOKUP(All_India_Index_Upto_April23__1___13[[#This Row],[Month]],Lookups!$E$1:$F$13,2,0) -> 4 | E13: Rural+Urban 2013 April | F13: 100.5 | G13: 111.6 | H13: 110.9 | I13: 106.6 | J13: 105.7 | K13: 104.4 | L13: 108.9 | M13: 105.5 | N13: 105.3 | O13: 103.5 | P13: 103.3 | Q13: 107.2 | R13: 109.6 | S13: 107.7 | T13: 107.5 | U13: 108 | V13: 107 | W13: 107.9 | X13: 100.5 | Y13: 106.5 | Z13: 106.3 | AA13: 105.3 | AB13: 104.7 | AC13: 104.2 | AD13: 105 | AE13: 102.9 | AF13: 104.8 | AG13: 106.1
... A373: Rural+Urban | B373: 2023 | C373: May | D373: =VLOOKUP(All_India_Index_Upto_April23__1___13[[#This Row],[Month]],Lookups!$E$1:$F$13,2,0) -> 5 | E373: Rural+Urban 2023 May | F373: 175.6 | G373: 173.7 | H373: 214.3 | I373: 173.2 | J373: 179.5 | K373: 170 | L373: 172.2 | M373: 161 | N373: 175.6 | O373: 122.7 | P373: 218 | Q373: 173.4 | R373: 194.2 | S373: 179.1 | T373: 201 | U373: 187.3 | V373: 179.7 | W373: 186.2 | X373: 175.6 | Y373: 182.8 | Z373: 175.2 | AA373: 185.7 | AB373: 164.8 | AC373: 171.2 | AD373: 177.1 | AE373: 185.2 | AF373: 175.7 | AG373: 179.1

Sheet Que1 General
A1: Sub-Category | B1: Categories | C1: Rural | D1: Urban | E1: General index | F1: Total | G1: General Index Contribution | H1: Essential | I1: Food and Beverages | J1: Healthcare | K1: Other
A2: Essential | B2: Housing Clean | C2: 175.6 | D2: 175.6 | E2: =AVERAGE(C2:D2) -> 175.6 | F2: =SUM(E2:E27) -> 4657.65 | G2: =(E2/$F$2)*100 -> 3.7701416 | H2: =SUMIF($A:$A,H$1,$G:$G) -> 30.603416 | I2: =SUMIF($A:$A,I$1,$G:$G) -> 53.996114 | J2: =SUMIF($A:$A,J$1,$G:$G) -> 7.9492877 | K2: =SUMIF($A:$A,K$1,$G:$G) -> 7.4511825
A3: Food and Beverages | B3: Cereals and products | C3: 173.2 | D3: 174.7 | E3: =AVERAGE(C3:D3) -> 173.95 | G3: =(E3/$F$2)*100 -> 3.734716
A4: Food and Beverages | B4: Meat and fish | C4: 211.5 | D4: 219.4 | E4: =AVERAGE(C4:D4) -> 215.45 | G4: =(E4/$F$2)*100 -> 4.6257233
A5: Food and Beverages | B5: Egg | C5: 171 | D5: 176.7 | E5: =AVERAGE(C5:D5) -> 173.85 | G5: =(E5/$F$2)*100 -> 3.732569
A6: Food and Beverages | B6: Milk and products | C6: 179.6 | D6: 179.4 | E6: =AVERAGE(C6:D6) -> 179.5 | G6: =(E6/$F$2)*100 -> 3.8538748
A7: Food and Beverages | B7: Oils and fats | C7: 173.3 | D7: 164.4 | E7: =AVERAGE(C7:D7) -> 168.85 | G7: =(E7/$F$2)*100 -> 3.6252187
A8: Food and Beverages | B8: Fruits | C8: 169 | D8: 175.8 | E8: =AVERAGE(C8:D8) -> 172.4 | G8: =(E8/$F$2)*100 -> 3.7014374
A9: Food and Beverages | B9: Vegetables | C9: 148.7 | D9: 185 | E9: =AVERAGE(C9:D9) -> 166.85 | G9: =(E9/$F$2)*100 -> 3.5822786
A10: Food and Beverages | B10: Pulses and products | C10: 174.9 | D10: 176.9 | E10: =AVERAGE(C10:D10) -> 175.9 | G10: =(E10/$F$2)*100 -> 3.7765826
A11: Food and Beverages | B11: Sugar and Confectionery | C11: 121.9 | D11: 124.2 | E11: =AVERAGE(C11:D11) -> 123.05 | G11: =(E11/$F$2)*100 -> 2.6418902
A12: Food and Beverages | B12: Spices | C12: 221 | D12: 211.9 | E12: =AVERAGE(C12:D12) -> 216.45 | G12: =(E12/$F$2)*100 -> 4.6471933
A13: Food and Beverages | B13: Non-alcoholic beverages | C13: 178.7 | D13: 165.9 | E13: =AVERAGE(C13:D13) -> 172.3 | G13: =(E13/$F$2)*100 -> 3.6992904
A14: Food and Beverages | B14: Prepared meals, snacks, sweets etc. | C14: 191.1 | D14: 197.7 | E14: =AVERAGE(C14:D14) -> 194.4 | G14: =(E14/$F$2)*100 -> 4.1737786
... A23: Essential | B23: Transport and communication | C23: 169.7 | D23: 160.4 | E23: =AVERAGE(C23:D23) -> 165.05 | G23: =(E23/$F$2)*100 -> 3.5436325
A24: Other | B24: Recreation and amusement | C24: 173.8 | D24: 169.2 | E24: =AVERAGE(C24:D24) -> 171.5 | G24: =(E24/$F$2)*100 -> 3.6821144 | I24: In general the Food and Beverages have the highest contribution as compared to other categories.
A25: Essential | B25: Education | C25: 180.3 | D25: 174.8 | E25: =AVERAGE(C25:D25) -> 177.55 | G25: =(E25/$F$2)*100 -> 3.8120082
A26: Healthcare | B26: Personal care and effects | C26: 184.9 | D26: 185.6 | E26: =AVERAGE(C26:D26) -> 185.25 | G26: =(E26/$F$2)*100 -> 3.9773276
A27: Other | B27: Miscellaneous | C27: 179.5 | D27: 171.6 | E27: =AVERAGE(C27:D27) -> 175.55 | G27: =(E27/$F$2)*100 -> 3.7690681

Sheet Que5 Grouping
E1: Food | F1: Food | G1: Food | H1: Food | I1: Food | J1: Food | K1: Food | L1: Food | M1: Food | N1: Food | O1: Food | P1: Food | Q1: Food | R1: Food | T1: Fuel and light | U1: Transport and communication | V1: General CPI
A2: Sector | B2: Year | C2: Month | D2: Index | E2: Cereals and products | F2: Meat and fish | G2: Egg | H2: Milk and products | I2: Oils and fats | J2: Fruits | K2: Vegetables | L2: Pulses and products | M2: Sugar and Confectionery | N2: Spices | O2: Non-alcoholic beverages | P2: Prepared meals, snacks, sweets etc. | Q2: Food and beverages | R2: Pan, tobacco and intoxicants | S2: Food | T2: Fuel and light | U2: Transport and communication | V2: General index
A3: Rural+Urban | B3: 2020 | C3: January | D3: 1 | E3: 144.3 | F3: 167.4 | G3: 154.9 | H3: 150.1 | I3: 129.9 | J3: 143.2 | K3: 197 | L3: 140.4 | M3: 114.1 | N3: 150.9 | O3: 136.1 | P3: 158.6 | Q3: 153.5 | R3: 169.2 | S3: =SUM(E3:R3) -> 2109.6 | T3: 144.6 | U3: 130.9 | V3: 150.2
A4: Rural+Urban | B4: 2020 | C4: February | D4: 2 | E4: 144.8 | F4: 167.5 | G4: 151.8 | H4: 150.8 | I4: 131.4 | J4: 141.8 | K4: 170.7 | L4: 141.1 | M4: 113.6 | N4: 152 | O4: 136.5 | P4: 159.1 | Q4: 150.5 | R4: 170.1 | S4: =SUM(E4:R4) -> 2081.7 | T4: 147.2 | U4: 130.3 | V4: 149.1
A5: Rural+Urban | B5: 2020 | C5: March | D5: 3 | E5: 145.1 | F5: 167 | G5: 148.1 | H5: 151.5 | I5: 131.2 | J5: 142.5 | K5: 157.3 | L5: 141.1 | M5: 113.2 | N5: 153.2 | O5: 136.7 | P5: 159.6 | Q5: 148.9 | R5: 171.2 | S5: =SUM(E5:R5) -> 2066.6 | T5: 148.9 | U5: 129.9 | V5: 148.6
A6: Rural+Urban | B6: 2020 | C6: April | D6: 4 | E6: 148.7 | F6: 167 | G6: 148.8 | H6: 155.6 | I6: 135.1 | J6: 149.9 | K6: 168.6 | L6: 150.4 | M6: 120.3 | N6: 157.1 | O6: 136.8 | P6: 159 | Q6: 151.4 | R6: 171 | S6: =SUM(E6:R6) -> 2119.7 | T6: 144.1 | U6: 130 | V6: 149
A7: Rural+Urban | B7: 2020 | C7: May | D7: 5 | E7: 147 | F7: 167 | G7: 148 | H7: 154 | I7: 133 | J7: 146 | K7: 163 | L7: 146 | M7: 117 | N7: 155 | O7: 137 | P7: 159 | Q7: 150 | R7: 171 | S7: =SUM(E7:R7) -> 2093 | T7: 147 | U7: 130 | V7: 149
A8: Rural+Urban | B8: 2020 | C8: June | D8: 6 | E8: 149.6 | F8: 192.7 | G8: 151.4 | H8: 153.3 | I8: 136.3 | J8: 147.2 | K8: 156.5 | L8: 150.9 | M8: 114.2 | N8: 159.5 | O8: 139.4 | P8: 161.8 | Q8: 154 | R8: 183.5 | S8: =SUM(E8:R8) -> 2150.3 | T8: 141.9 | U8: 135 | V8: 151.8
A9: Rural+Urban | B9: 2020 | C9: July | D9: 7 | E9: 149.6 | F9: 192.7 | G9: 151.4 | H9: 153.3 | I9: 136.3 | J9: 147.2 | K9: 156.5 | L9: 150.9 | M9: 114.2 | N9: 159.5 | O9: 139.4 | P9: 161.8 | Q9: 154 | R9: 183.5 | S9: =SUM(E9:R9) -> 2150.3 | T9: 141.9 | U9: 135 | V9: 151.8
A10: Rural+Urban | B10: 2020 | C10: August | D10: 8 | E10: 148.9 | F10: 190.9 | G10: 150.8 | H10: 153.3 | I10: 137.4 | J10: 150.4 | K10: 178.1 | L10: 150.4 | M10: 115.1 | N10: 160 | O10: 140.6 | P10: 162.3 | Q10: 157 | R10: 182.6 | S10: =SUM(E10:R10) -> 2177.8 | T10: 143 | U10: 138.5 | V10: 153.9
A11: Rural+Urban | B11: 2020 | C11: September | D11: 9 | E11: 148.4 | F11: 187.1 | G11: 152.5 | H11: 153.6 | I11: 138.2 | J11: 150.9 | K11: 186.7 | L11: 149.8 | M11: 116.4 | N11: 160.3 | O11: 142.2 | P11: 162.9 | Q11: 158 | R11: 184.4 | S11: =SUM(E11:R11) -> 2191.4 | T11: 142.9 | U11: 139.6 | V11: 154.7
A12: Rural+Urban | B12: 2020 | C12: October | D12: 10 | E12: 147.5 | F12: 188.9 | G12: 161.4 | H12: 153.6 | I12: 140.1 | J12: 151.2 | K12: 209.2 | L12: 150.9 | M12: 116.2 | N12: 161 | O12: 144 | P12: 163.2 | Q12: 161.4 | R12: 184.3 | S12: =SUM(E12:R12) -> 2232.9 | T12: 143.1 | U12: 140.6 | V12: 156.4
A13: Rural+Urban | B13: 2020 | C13: November | D13: 11 | E13: 146.8 | F13: 191 | G13: 173.6 | H13: 153.8 | I13: 142.7 | J13: 148.4 | K13: 230 | L13: 156.8 | M13: 115.7 | N13: 161.8 | O13: 146.5 | P13: 163.8 | Q13: 164.7 | R13: 184.8 | S13: =SUM(E13:R13) -> 2280.4 | T13: 143.6 | U13: 140.4 | V13: 158.4
A14: Rural+Urban | B14: 2020 | C14: December | D14: 12 | E14: 146 | F14: 191 | G14: 175.3 | H14: 154.1 | I14: 146.6 | J14: 147.7 | K14: 230.5 | L14: 160.2 | M14: 115.3 | N14: 163 | O14: 149.2 | P14: 164.8 | Q14: 165.4 | R14: 185.4 | S14: =SUM(E14:R14) -> 2294.5 | T14: 144.6 | U14: 140.7 | V14: 158.9
... A43: Rural+Urban | B43: 2023 | C43: May | D43: 5 | E43: 173.7 | F43: 214.3 | G43: 173.2 | H43: 179.5 | I43: 170 | J43: 172.2 | K43: 161 | L43: 175.6 | M43: 122.7 | N43: 218 | O43: 173.4 | P43: 194.2 | Q43: 179.1 | R43: 201 | S43: =SUM(E43:R43) -> 2507.9 | T43: 182.8 | U43: 164.8 | V43: 179.1

Sheet Crude oil (2)
A1: Year N Month | B1: Crude Oil Price | C1: Exchange Rate
A2: 43831 | B2: 57.52 | C2: =VLOOKUP(A2,[1]Sheet2!M$5:N$45,2,0) -> 71.26787 | D2: =B2*C2 -> 4099.3279
A3: 43862 | B3: 50.54 | C3: =VLOOKUP(A3,[1]Sheet2!M$5:N$45,2,0) -> 71.53615 | D3: =B3*C3 -> 3615.437
A4: 43891 | B4: 29.21 | C4: =VLOOKUP(A4,[1]Sheet2!M$5:N$45,2,0) -> 74.564955 | D4: =B4*C4 -> 2178.0423
A5: 43922 | B5: 16.55 | C5: =VLOOKUP(A5,[1]Sheet2!M$5:N$45,2,0) -> 76.178409 | D5: =B5*C5 -> 1260.7527
A6: 43952 | B6: 28.56 | C6: =VLOOKUP(A6,[1]Sheet2!M$5:N$45,2,0) -> 75.674952 | D6: =B6*C6 -> 2161.2766
A7: 43983 | B7: 38.31 | C7: =VLOOKUP(A7,[1]Sheet2!M$5:N$45,2,0) -> 75.723136 | D7: =B7*C7 -> 2900.9534
A8: 44013 | B8: 40.71 | C8: =VLOOKUP(A8,[1]Sheet2!M$5:N$45,2,0) -> 74.928826 | D8: =B8*C8 -> 3050.3525
A9: 44044 | B9: 42.34 | C9: =VLOOKUP(A9,[1]Sheet2!M$5:N$45,2,0) -> 74.569762 | D9: =B9*C9 -> 3157.2837
A10: 44075 | B10: 39.63 | C10: =VLOOKUP(A10,[1]Sheet2!M$5:N$45,2,0) -> 73.518273 | D10: =B10*C10 -> 2913.5291
A11: 44105 | B11: 39.4 | C11: =VLOOKUP(A11,[1]Sheet2!M$5:N$45,2,0) -> 73.5585 | D11: =B11*C11 -> 2898.2049
A12: 44136 | B12: 40.94 | C12: =VLOOKUP(A12,[1]Sheet2!M$5:N$45,2,0) -> 74.217524 | D12: =B12*C12 -> 3038.4654
A13: 44166 | B13: 47.02 | C13: =VLOOKUP(A13,[1]Sheet2!M$5:N$45,2,0) -> 73.630304 | D13: =B13*C13 -> 3462.0969
... A42: 45047 | B42: 71.58 | C42: =VLOOKUP(A42,[1]Sheet2!M$5:N$45,2,0) -> 82.295261 | D42: =B42*C42 -> 5890.6948

Sheet Que1-Rural+Urban
A1: Sub-Category | B1: Categories | C1: Rural+Urban | D1: Total | E1: Contribution Rural+Urban | F1: Essential | G1: Food and Beverages | H1: Healthcare | I1: Other
A2: Essential | B2: Housing Clean | C2: 175.6 | D2: =SUM(C2:C27) -> 4654.4 | E2: =(C2/$D$2)*100 -> 3.7727741 | F2: =SUMIF(A:A,F1,E:E) -> 30.695686 | G2: =SUMIF(A:A,G1,E:E) -> 53.882348 | H2: =SUMIF(A:A,H1,E:E) -> 7.9688037 | I2: =SUMIF(A:A,I1,E:E) -> 7.4531626
A3: Food and Beverages | B3: Cereals and products | C3: 173.7 | E3: =(C3/$D$2)*100 -> 3.7319526
A4: Food and Beverages | B4: Meat and fish | C4: 214.3 | E4: =(C4/$D$2)*100 -> 4.6042454
A5: Food and Beverages | B5: Egg | C5: 173.2 | E5: =(C5/$D$2)*100 -> 3.72121
A6: Food and Beverages | B6: Milk and products | C6: 179.5 | E6: =(C6/$D$2)*100 -> 3.8565658
A7: Food and Beverages | B7: Oils and fats | C7: 170 | E7: =(C7/$D$2)*100 -> 3.6524579
A8: Food and Beverages | B8: Fruits | C8: 172.2 | E8: =(C8/$D$2)*100 -> 3.699725
A9: Food and Beverages | B9: Vegetables | C9: 161 | E9: =(C9/$D$2)*100 -> 3.4590925
A10: Food and Beverages | B10: Pulses and products | C10: 175.6 | E10: =(C10/$D$2)*100 -> 3.7727741
A11: Food and Beverages | B11: Sugar and Confectionery | C11: 122.7 | E11: =(C11/$D$2)*100 -> 2.6362152
A12: Food and Beverages | B12: Spices | C12: 218 | E12: =(C12/$D$2)*100 -> 4.6837401
A13: Food and Beverages | B13: Non-alcoholic beverages | C13: 173.4 | E13: =(C13/$D$2)*100 -> 3.725507
A14: Food and Beverages | B14: Prepared meals, snacks, sweets etc. | C14: 194.2 | E14: =(C14/$D$2)*100 -> 4.172396
... A22: Healthcare | B22: Health | C22: 185.7 | E22: =(C22/$D$2)*100 -> 3.9897731
A23: Essential | B23: Transport and communication | C23: 164.8 | E23: =(C23/$D$2)*100 -> 3.5407356 | G23: For Rural+Urban Sector Food and Beverages has the Highest Contribution to the inflamation as compared to other categories.
A24: Other | B24: Recreation and amusement | C24: 171.2 | E24: =(C24/$D$2)*100 -> 3.6782399
A25: Essential | B25: Education | C25: 177.1 | E25: =(C25/$D$2)*100 -> 3.8050017
A26: Healthcare | B26: Personal care and effects | C26: 185.2 | E26: =(C26/$D$2)*100 -> 3.9790306
A27: Other | B27: Miscellaneous | C27: 175.7 | E27: =(C27/$D$2)*100 -> 3.7749227

Sheet Que1-Urban
A1: Sub-Category | B1: Categories | C1: Urban | D1: Total | E1: Contribution | F1: Essential | G1: Food and Beverages | H1: Healthcare | I1: Other
A2: Essential | B2: Housing Clean | C2: 175.6 | D2: =SUM(C2:C27) -> 4640.9 | E2: =(C2/$D$2)*100 -> 3.7837488 | F2: =SUMIF($A:$A,F$1,$E:$E) -> 30.01573 | G2: =SUMIF($A:$A,G$1,$E:$E) -> 54.71568 | H2: =SUMIF($A:$A,H$1,$E:$E) -> 7.9251869 | I2: =SUMIF($A:$A,I$1,$E:$E) -> 7.3434032
A3: Food and Beverages | B3: Cereals and products | C3: 174.7 | E3: =(C3/$D$2)*100 -> 3.7643561
A4: Food and Beverages | B4: Meat and fish | C4: 219.4 | E4: =(C4/$D$2)*100 -> 4.7275313
A5: Food and Beverages | B5: Egg | C5: 176.7 | E5: =(C5/$D$2)*100 -> 3.8074511
A6: Food and Beverages | B6: Milk and products | C6: 179.4 | E6: =(C6/$D$2)*100 -> 3.8656295
A7: Food and Beverages | B7: Oils and fats | C7: 164.4 | E7: =(C7/$D$2)*100 -> 3.5424163
A8: Food and Beverages | B8: Fruits | C8: 175.8 | E8: =(C8/$D$2)*100 -> 3.7880584
A9: Food and Beverages | B9: Vegetables | C9: 185 | E9: =(C9/$D$2)*100 -> 3.9862958
A10: Food and Beverages | B10: Pulses and products | C10: 176.9 | E10: =(C10/$D$2)*100 -> 3.8117606
A11: Food and Beverages | B11: Sugar and Confectionery | C11: 124.2 | E11: =(C11/$D$2)*100 -> 2.676205
A12: Food and Beverages | B12: Spices | C12: 211.9 | E12: =(C12/$D$2)*100 -> 4.5659247
A13: Food and Beverages | B13: Non-alcoholic beverages | C13: 165.9 | E13: =(C13/$D$2)*100 -> 3.5747377
A14: Food and Beverages | B14: Prepared meals, snacks, sweets etc. | C14: 197.7 | E14: =(C14/$D$2)*100 -> 4.2599496
... A22: Healthcare | B22: Health | C22: 182.2 | E22: =(C22/$D$2)*100 -> 3.9259626
A23: Essential | B23: Transport and communication | C23: 160.4 | E23: =(C23/$D$2)*100 -> 3.4562262 | G23: For Urban Sector Food and Beverages has the highest contribution towards inflamation as compared to other categories.
A24: Other | B24: Recreation and amusement | C24: 169.2 | E24: =(C24/$D$2)*100 -> 3.6458446
A25: Essential | B25: Education | C25: 174.8 | E25: =(C25/$D$2)*100 -> 3.7665108
A26: Healthcare | B26: Personal care and effects | C26: 185.6 | E26: =(C26/$D$2)*100 -> 3.9992243
A27: Other | B27: Miscellaneous | C27: 171.6 | E27: =(C27/$D$2)*100 -> 3.6975587

Sheet Que1-Rural
A1: Sub-Category | B1: Categories | C1: Rural | D1: Total | E1: Contribution | F1: Essential | G1: Food and Beverages | H1: Healthcare | I1: Other
A2: Essential | B2: Housing Clean | C2: 175.6 | D2: =SUM(C2:C27) -> 4674.4 | E2: =(C2/$D$2)*100 -> 3.7566319 | F2: =SUMIF($A:$A,F$1,$E:$E) -> 31.18689 | G2: =SUMIF($A:$A,G$1,$E:$E) -> 53.281705 | H2: =SUMIF($A:$A,H$1,$E:$E) -> 7.9732158 | I2: =SUMIF($A:$A,I$1,$E:$E) -> 7.5581893
A3: Food and Beverages | B3: Cereals and products | C3: 173.2 | E3: =(C3/$D$2)*100 -> 3.7052884
A4: Food and Beverages | B4: Meat and fish | C4: 211.5 | E4: =(C4/$D$2)*100 -> 4.5246449
A5: Food and Beverages | B5: Egg | C5: 171 | E5: =(C5/$D$2)*100 -> 3.6582235
A6: Food and Beverages | B6: Milk and products | C6: 179.6 | E6: =(C6/$D$2)*100 -> 3.8422043
A7: Food and Beverages | B7: Oils and fats | C7: 173.3 | E7: =(C7/$D$2)*100 -> 3.7074277
A8: Food and Beverages | B8: Fruits | C8: 169 | E8: =(C8/$D$2)*100 -> 3.6154373
A9: Food and Beverages | B9: Vegetables | C9: 148.7 | E9: =(C9/$D$2)*100 -> 3.1811569
A10: Food and Beverages | B10: Pulses and products | C10: 174.9 | E10: =(C10/$D$2)*100 -> 3.7416567
A11: Food and Beverages | B11: Sugar and Confectionery | C11: 121.9 | E11: =(C11/$D$2)*100 -> 2.6078213
A12: Food and Beverages | B12: Spices | C12: 221 | E12: =(C12/$D$2)*100 -> 4.7278795
A13: Food and Beverages | B13: Non-alcoholic beverages | C13: 178.7 | E13: =(C13/$D$2)*100 -> 3.8229505
A14: Food and Beverages | B14: Prepared meals, snacks, sweets etc. | C14: 191.1 | E14: =(C14/$D$2)*100 -> 4.0882252
... A21: Essential | B21: Household goods and services | C21: 179.8 | E21: =(C21/$D$2)*100 -> 3.846483
A22: Healthcare | B22: Health | C22: 187.8 | E22: =(C22/$D$2)*100 -> 4.0176279 | G22: For the Rural Sector Food and Beverages has the highest contribution amongst other categories.
A23: Essential | B23: Transport and communication | C23: 169.7 | E23: =(C23/$D$2)*100 -> 3.6304125
A24: Other | B24: Recreation and amusement | C24: 173.8 | E24: =(C24/$D$2)*100 -> 3.7181243
A25: Essential | B25: Education | C25: 180.3 | E25: =(C25/$D$2)*100 -> 3.8571795
A26: Healthcare | B26: Personal care and effects | C26: 184.9 | E26: =(C26/$D$2)*100 -> 3.9555879
A27: Other | B27: Miscellaneous | C27: 179.5 | E27: =(C27/$D$2)*100 -> 3.840065

Sheet Question 2
E1: Food and Beverages | F1: Food and Beverages | G1: Food and Beverages | H1: Food and Beverages | I1: Food and Beverages | J1: Food and Beverages | K1: Food and Beverages | L1: Food and Beverages | M1: Food and Beverages | N1: Food and Beverages | O1: Food and Beverages | P1: Food and Beverages | Q1: Food and Beverages | R1: Food and Beverages | T1: Essential | U1: Essential | V1: Essential | W1: Essential | X1: Essential | Y1: Essential | Z1: Essential | AA1: Essential | AC1: Healthcare | AD1: Healthcare | AF1: Miscellaneous | AG1: Miscellaneous | AI1: General CPI
A2: Sector | B2: Year | C2: Month | D2: Index | E2: Cereals and products | F2: Meat and fish | G2: Egg | H2: Milk and products | I2: Oils and fats | J2: Fruits | K2: Vegetables | L2: Pulses and products | M2: Sugar and Confectionery | N2: Spices | O2: Non-alcoholic beverages | P2: Prepared meals, snacks, sweets etc. | Q2: Food and beverages | R2: Pan, tobacco and intoxicants | S2: Food and Beverages | T2: Housing Clean | U2: Clothing | V2: Footwear | W2: Clothing and footwear | X2: Fuel and light | Y2: Household goods and services | Z2: Transport and communication | AA2: Education | AB2: Essential | AC2: Health | AD2: Personal care and effects | AE2: Healthcare | AF2: Recreation and amusement | AG2: Miscellaneous | AH2: Miscellaneous | AI2: General index
A3: Rural+Urban | B3: 2016 | C3: January | D3: 1 | E3: 126.1 | F3: 134.1 | G3: 128.6 | H3: 129.9 | I3: 115.5 | J3: 125.7 | K3: 141.5 | L3: 170.7 | M3: 97.4 | N3: 132.9 | O3: 122.7 | P3: 135.3 | Q3: 131.3 | R3: 135.2 | S3: =SUM(E3:R3) -> 1826.9 | T3: 123.4 | U3: 130.3 | V3: 125.1 | W3: 129.5 | X3: 122.7 | Y3: 124.2 | Z3: 111.1 | AA3: 126.3 | AB3: =SUM(T3:AA3) -> 992.6 | AC3: 122 | AD3: 114.5 | AE3: =SUM(AC3:AD3) -> 236.5 | AF3: 119.8 | AG3: 118.5 | AH3: =SUM(AF3:AG3) -> 238.3 | AI3: 126.3
A4: Rural+Urban | B4: 2016 | C4: February | D4: 2 | E4: 126.4 | F4: 134.2 | G4: 128.7 | H4: 130.3 | I4: 114.8 | J4: 124.9 | K4: 130.3 | L4: 167.4 | M4: 98.8 | N4: 133.6 | O4: 123 | P4: 135.8 | Q4: 129.9 | R4: 135.9 | S4: =SUM(E4:R4) -> 1814 | T4: 124.4 | U4: 130.9 | V4: 125.8 | W4: 130.2 | X4: 123.1 | Y4: 124.6 | Z4: 111.4 | AA4: 126.6 | AB4: =SUM(T4:AA4) -> 997 | AC4: 122.5 | AD4: 116.6 | AE4: =SUM(AC4:AD4) -> 239.1 | AF4: 120.3 | AG4: 119.1 | AH4: =SUM(AF4:AG4) -> 239.4 | AI4: 126
A5: Rural+Urban | B5: 2016 | C5: March | D5: 3 | E5: 126.5 | F5: 135.1 | G5: 124.6 | H5: 130.2 | I5: 114.5 | J5: 126.2 | K5: 129.8 | L5: 164.3 | M5: 100.9 | N5: 133.9 | O5: 123.1 | P5: 136.3 | Q5: 129.8 | R5: 136.5 | S5: =SUM(E5:R5) -> 1811.7 | T5: 124.9 | U5: 131.3 | V5: 126.1 | W5: 130.5 | X5: 122.4 | Y5: 125.1 | Z5: 110.9 | AA5: 126.9 | AB5: =SUM(T5:AA5) -> 998.1 | AC5: 122.9 | AD5: 117.3 | AE5: =SUM(AC5:AD5) -> 240.2 | AF5: 120.6 | AG5: 119.3 | AH5: =SUM(AF5:AG5) -> 239.9 | AI5: 126
A6: Rural+Urban | B6: 2016 | C6: April | D6: 4 | E6: 126.6 | F6: 136.8 | G6: 122 | H6: 130.9 | I6: 114.8 | J6: 134.8 | K6: 135 | L6: 167.5 | M6: 106.4 | N6: 134.4 | O6: 123.6 | P6: 136.7 | Q6: 131.8 | R6: 137.1 | S6: =SUM(E6:R6) -> 1838.4 | T6: 125.6 | U6: 131.8 | V6: 126.4 | W6: 131 | X6: 122.3 | Y6: 125.5 | Z6: 112.1 | AA6: 127.7 | AB6: =SUM(T6:AA6) -> 1002.4 | AC6: 123.2 | AD6: 118.1 | AE6: =SUM(AC6:AD6) -> 241.3 | AF6: 121.1 | AG6: 120 | AH6: =SUM(AF6:AG6) -> 241.1 | AI6: 127.3
A7: Rural+Urban | B7: 2016 | C7: May | D7: 5 | E7: 126.8 | F7: 139.1 | G7: 125.4 | H7: 131.7 | I7: 115 | J7: 136 | K7: 145.1 | L7: 171.7 | M7: 108.7 | N7: 135.3 | O7: 124.2 | P7: 137.4 | Q7: 134 | R7: 137.7 | S7: =SUM(E7:R7) -> 1868.1 | T7: 126 | U7: 132.2 | V7: 126.8 | W7: 131.4 | X7: 122.7 | Y7: 126 | Z7: 112.8 | AA7: 128.5 | AB7: =SUM(T7:AA7) -> 1006.4 | AC7: 123.7 | AD7: 119.2 | AE7: =SUM(AC7:AD7) -> 242.9 | AF7: 121.5 | AG7: 120.7 | AH7: =SUM(AF7:AG7) -> 242.2 | AI7: 128.6
A8: Rural+Urban | B8: 2016 | C8: June | D8: 6 | E8: 127.7 | F8: 140.5 | G8: 128.3 | H8: 132.6 | I8: 115.5 | J8: 136.5 | K8: 159.7 | L8: 174.3 | M8: 109.9 | N8: 136.3 | O8: 124.4 | P8: 138.1 | Q8: 136.8 | R8: 138.7 | S8: =SUM(E8:R8) -> 1899.3 | T8: 125.5 | U8: 132.9 | V8: 127.2 | W8: 132 | X8: 123.3 | Y8: 126.4 | Z8: 114.2 | AA8: 129.7 | AB8: =SUM(T8:AA8) -> 1011.2 | AC8: 124.1 | AD8: 119.4 | AE8: =SUM(AC8:AD8) -> 243.5 | AF8: 121.7 | AG8: 121.5 | AH8: =SUM(AF8:AG8) -> 243.2 | AI8: 130.1
A9: Rural+Urban | B9: 2016 | C9: July | D9: 7 | E9: 128.5 | F9: 141.2 | G9: 132.3 | H9: 133.5 | I9: 116.4 | J9: 137.8 | K9: 165.4 | L9: 177.4 | M9: 111.3 | N9: 137.5 | O9: 125 | P9: 138.8 | Q9: 138.4 | R9: 139.3 | S9: =SUM(E9:R9) -> 1922.8 | T9: 126.4 | U9: 133.5 | V9: 127.6 | W9: 132.7 | X9: 123.4 | Y9: 126.9 | Z9: 113.9 | AA9: 130.8 | AB9: =SUM(T9:AA9) -> 1015.2 | AC9: 124.5 | AD9: 120.5 | AE9: =SUM(AC9:AD9) -> 245 | AF9: 122.4 | AG9: 121.9 | AH9: =SUM(AF9:AG9) -> 244.3 | AI9: 131.1
A10: Rural+Urban | B10: 2016 | C10: August | D10: 8 | E10: 129.3 | F10: 139.3 | G10: 131.6 | H10: 134.1 | I10: 116.9 | J10: 138.1 | K10: 159.1 | L10: 175.6 | M10: 112.9 | N10: 138.1 | O10: 125.5 | P10: 139.5 | Q10: 137.9 | R10: 140.2 | S10: =SUM(E10:R10) -> 1918.1 | T10: 127.3 | U10: 134.1 | V10: 128.2 | W10: 133.2 | X10: 123.6 | Y10: 127.4 | Z10: 113.1 | AA10: 131.7 | AB10: =SUM(T10:AA10) -> 1018.6 | AC10: 124.8 | AD10: 121.5 | AE10: =SUM(AC10:AD10) -> 246.3 | AF10: 122.7 | AG10: 122.1 | AH10: =SUM(AF10:AG10) -> 244.8 | AI10: 131.1
A11: Rural+Urban | B11: 2016 | C11: September | D11: 9 | E11: 129.9 | F11: 138 | G11: 130.5 | H11: 134.4 | I11: 117.2 | J11: 136.1 | K11: 150.7 | L11: 171.5 | M11: 113.8 | N11: 138.8 | O11: 126 | P11: 140.2 | Q11: 136.6 | R11: 141 | S11: =SUM(E11:R11) -> 1904.7 | T11: 127.9 | U11: 134.6 | V11: 128.6 | W11: 133.8 | X11: 124.1 | Y11: 127.9 | Z11: 114.3 | AA11: 131.8 | AB11: =SUM(T11:AA11) -> 1023 | AC11: 125.4 | AD11: 122.1 | AE11: =SUM(AC11:AD11) -> 247.5 | AF11: 122.9 | AG11: 122.8 | AH11: =SUM(AF11:AG11) -> 245.7 | AI11: 130.9
A12: Rural+Urban | B12: 2016 | C12: October | D12: 10 | E12: 130.5 | F12: 137.9 | G12: 130.2 | H12: 134.8 | I12: 117.8 | J12: 134.7 | K12: 151.2 | L12: 172.1 | M12: 114.1 | N12: 139.3 | O12: 126.1 | P12: 141.1 | Q12: 137 | R12: 141.8 | S12: =SUM(E12:R12) -> 1908.6 | T12: 128.7 | U12: 135.5 | V12: 129.1 | W12: 134.5 | X12: 124.3 | Y12: 128.4 | Z12: 115.2 | AA12: 132.4 | AB12: =SUM(T12:AA12) -> 1028.1 | AC12: 126.1 | AD12: 122.1 | AE12: =SUM(AC12:AD12) -> 248.2 | AF12: 123.5 | AG12: 123.4 | AH12: =SUM(AF12:AG12) -> 246.9 | AI12: 131.4
A13: Rural+Urban | B13: 2016 | C13: November | D13: 11 | E13: 131.4 | F13: 137.8 | G13: 132 | H13: 135 | I13: 118 | J13: 134.1 | K13: 141.9 | L13: 171.7 | M13: 114.1 | N13: 139.7 | O13: 126.2 | P13: 141.8 | Q13: 136.1 | R13: 142 | S13: =SUM(E13:R13) -> 1901.8 | T13: 129.1 | U13: 135.8 | V13: 129.3 | W13: 135 | X13: 125 | Y13: 128.6 | Z13: 115.7 | AA13: 132.8 | AB13: =SUM(T13:AA13) -> 1031.3 | AC13: 126.4 | AD13: 122.6 | AE13: =SUM(AC13:AD13) -> 249 | AF13: 124 | AG13: 123.8 | AH13: =SUM(AF13:AG13) -> 247.8 | AI13: 131.2
A14: Rural+Urban | B14: 2016 | C14: December | D14: 12 | E14: 132.3 | F14: 137.6 | G14: 132.9 | H14: 135.1 | I14: 118.6 | J14: 132.7 | K14: 125.3 | L14: 168.7 | M14: 114.4 | N14: 140.2 | O14: 126.6 | P14: 142.3 | Q14: 134 | R14: 143.1 | S14: =SUM(E14:R14) -> 1883.8 | T14: 128.5 | U14: 136.3 | V14: 129.8 | W14: 135.4 | X14: 126.6 | Y14: 129.2 | Z14: 116 | AA14: 133.1 | AB14: =SUM(T14:AA14) -> 1034.9 | AC14: 126.9 | AD14: 121.1 | AE14: =SUM(AC14:AD14) -> 248 | AF14: 124.2 | AG14: 123.9 | AH14: =SUM(AF14:AG14) -> 248.1 | AI14: 130.4
... A90: Rural+Urban | B90: 2023 | C90: May | D90: 5 | E90: 173.7 | F90: 214.3 | G90: 173.2 | H90: 179.5 | I90: 170 | J90: 172.2 | K90: 161 | L90: 175.6 | M90: 122.7 | N90: 218 | O90: 173.4 | P90: 194.2 | Q90: 179.1 | R90: 201 | S90: =SUM(E90:R90) -> 2507.9 | T90: 175.6 | U90: 187.3 | V90: 179.7 | W90: 186.2 | X90: 182.8 | Y90: 175.2 | Z90: 164.8 | AA90: 177.1 | AB90: =SUM(T90:AA90) -> 1428.7 | AC90: 185.7 | AD90: 185.2 | AE90: =SUM(AC90:AD90) -> 370.9 | AF90: 171.2 | AG90: 175.7 | AH90: =SUM(AF90:AG90) -> 346.9 | AI90: 179.1

Sheet Question 2 inflamation
A1: Sector | B1: Year | C1: Month | D1: Index | E1: Food and Beverages | F1: Food and Beverages Inflamation | G1: Essential | H1: Essential Inflamation | I1: Healthcare | J1: Healthcare Inflamation | K1: Miscellaneous | L1: Miscellaneous Inflamation | M1: General CPI | N1: General CPI Inflamation
A2: Rural+Urban | B2: 2016 | C2: January | D2: 1 | E2: 1826.9 | G2: 992.6 | I2: 236.5 | K2: 238.3 | M2: 126.3
A3: Rural+Urban | B3: 2016 | C3: February | D3: 2 | E3: 1814 | G3: 997 | I3: 239.1 | K3: 239.4 | M3: 126
A4: Rural+Urban | B4: 2016 | C4: March | D4: 3 | E4: 1811.7 | G4: 998.1 | I4: 240.2 | K4: 239.9 | M4: 126
A5: Rural+Urban | B5: 2016 | C5: April | D5: 4 | E5: 1838.4 | G5: 1002.4 | I5: 241.3 | K5: 241.1 | M5: 127.3
A6: Rural+Urban | B6: 2016 | C6: May | D6: 5 | E6: 1868.1 | G6: 1006.4 | I6: 242.9 | K6: 242.2 | M6: 128.6
A7: Rural+Urban | B7: 2016 | C7: June | D7: 6 | E7: 1899.3 | G7: 1011.2 | I7: 243.5 | K7: 243.2 | M7: 130.1
A8: Rural+Urban | B8: 2016 | C8: July | D8: 7 | E8: 1922.8 | G8: 1015.2 | I8: 245 | K8: 244.3 | M8: 131.1
A9: Rural+Urban | B9: 2016 | C9: August | D9: 8 | E9: 1918.1 | G9: 1018.6 | I9: 246.3 | K9: 244.8 | M9: 131.1
A10: Rural+Urban | B10: 2016 | C10: September | D10: 9 | E10: 1904.7 | G10: 1023 | I10: 247.5 | K10: 245.7 | M10: 130.9
A11: Rural+Urban | B11: 2016 | C11: October | D11: 10 | E11: 1908.6 | G11: 1028.1 | I11: 248.2 | K11: 246.9 | M11: 131.4
A12: Rural+Urban | B12: 2016 | C12: November | D12: 11 | E12: 1901.8 | G12: 1031.3 | I12: 249 | K12: 247.8 | M12: 131.2
A13: Rural+Urban | B13: 2016 | C13: December | D13: 12 | E13: 1883.8 | G13: 1034.9 | I13: 248 | K13: 248.1 | M13: 130.4
A14: Rural+Urban | B14: 2017 | C14: January | D14: 1 | E14: 1871.1 | F14: =((E14-E2)/E2)*100 -> 2.419399 | G14: 1038.5 | H14: =((G14-G2)/G2)*100 -> 4.6242192 | I14: 248.8 | J14: =((I14-I2)/I2)*100 -> 5.2008457 | K14: 248.6 | L14: =((K14-K2)/K2)*100 -> 4.3222828 | M14: 130.3 | N14: =((M14-M2)/M2)*100 -> 3.1670625
A15: Rural+Urban | B15: 2017 | C15: February | D15: 2 | E15: 1866.7 | F15: =((E15-E3)/E3)*100 -> 2.9051819 | G15: 1041.9 | H15: =((G15-G3)/G3)*100 -> 4.5035105 | I15: 250 | J15: =((I15-I3)/I3)*100 -> 4.558762 | K15: 249.4 | L15: =((K15-K3)/K3)*100 -> 4.1771094 | M15: 130.6 | N15: =((M15-M3)/M3)*100 -> 3.6507937
A16: Rural+Urban | B16: 2017 | C16: March | D16: 3 | E16: 1864 | F16: =((E16-E4)/E4)*100 -> 2.8867914 | G16: 1046 | H16: =((G16-G4)/G4)*100 -> 4.7991183 | I16: 250.4 | J16: =((I16-I4)/I4)*100 -> 4.2464613 | K16: 250.1 | L16: =((K16-K4)/K4)*100 -> 4.2517716 | M16: 130.9 | N16: =((M16-M4)/M4)*100 -> 3.8888889
A17: Rural+Urban | B17: 2017 | C17: April | D17: 4 | E17: 1863.8 | F17: =((E17-E5)/E5)*100 -> 1.3816362 | G17: 1049.1 | H17: =((G17-G5)/G5)*100 -> 4.6588188 | I17: 251.2 | J17: =((I17-I5)/I5)*100 -> 4.1027766 | K17: 250.2 | L17: =((K17-K5)/K5)*100 -> 3.7743675 | M17: 131.1 | N17: =((M17-M5)/M5)*100 -> 2.9850746
A18: Rural+Urban | B18: 2017 | C18: May | D18: 5 | E18: 1865.8 | F18: =((E18-E6)/E6)*100 -> -0.12311975 | G18: 1050.7 | H18: =((G18-G6)/G6)*100 -> 4.4018283 | I18: 251.4 | J18: =((I18-I6)/I6)*100 -> 3.4993825 | K18: 251 | L18: =((K18-K6)/K6)*100 -> 3.6333609 | M18: 131.4 | N18: =((M18-M6)/M6)*100 -> 2.1772939
A19: Rural+Urban | B19: 2017 | C19: June | D19: 6 | E19: 1881.2 | F19: =((E19-E7)/E7)*100 -> -0.95298268 | G19: 1051 | H19: =((G19-G7)/G7)*100 -> 3.9359177 | I19: 251.9 | J19: =((I19-I7)/I7)*100 -> 3.449692 | K19: 251.4 | L19: =((K19-K7)/K7)*100 -> 3.3717105 | M19: 132 | N19: =((M19-M7)/M7)*100 -> 1.4604151
A20: Rural+Urban | B20: 2017 | C20: July | D20: 7 | E20: 1917.6 | F20: =((E20-E8)/E8)*100 -> -0.27043894 | G20: 1056.4 | H20: =((G20-G8)/G8)*100 -> 4.0583136 | I20: 253 | J20: =((I20-I8)/I8)*100 -> 3.2653061 | K20: 252.5 | L20: =((K20-K8)/K8)*100 -> 3.3565289 | M20: 134.2 | N20: =((M20-M8)/M8)*100 -> 2.3646072
A21: Rural+Urban | B21: 2017 | C21: August | D21: 8 | E21: 1933.6 | F21: =((E21-E9)/E9)*100 -> 0.80809134 | G21: 1064.5 | H21: =((G21-G9)/G9)*100 -> 4.506185 | I21: 254.7 | J21: =((I21-I9)/I9)*100 -> 3.410475 | K21: 254.1 | L21: =((K21-K9)/K9)*100 -> 3.7990196 | M21: 135.4 | N21: =((M21-M9)/M9)*100 -> 3.279939
A22: Rural+Urban | B22: 2017 | C22: September | D22: 9 | E22: 1920.8 | F22: =((E22-E10)/E10)*100 -> 0.84527747 | G22: 1070.2 | H22: =((G22-G10)/G10)*100 -> 4.6138807 | I22: 256.3 | J22: =((I22-I10)/I10)*100 -> 3.5555556 | K22: 255.4 | L22: =((K22-K10)/K10)*100 -> 3.9479039 | M22: 135.2 | N22: =((M22-M10)/M10)*100 -> 3.2849503
A23: Rural+Urban | B23: 2017 | C23: October | D23: 10 | E23: 1931.3 | F23: =((E23-E11)/E11)*100 -> 1.1893535 | G23: 1075.7 | H23: =((G23-G11)/G11)*100 -> 4.6298998 | I23: 257.5 | J23: =((I23-I11)/I11)*100 -> 3.7469782 | K23: 256.1 | L23: =((K23-K11)/K11)*100 -> 3.7262049 | M23: 136.1 | N23: =((M23-M11)/M11)*100 -> 3.5768645
A24: Rural+Urban | B24: 2017 | C24: November | D24: 11 | E24: 1961.4 | F24: =((E24-E12)/E12)*100 -> 3.1338732 | G24: 1084.8 | H24: =((G24-G12)/G12)*100 -> 5.1876273 | I24: 259.4 | J24: =((I24-I12)/I12)*100 -> 4.1767068 | K24: 257.3 | L24: =((K24-K12)/K12)*100 -> 3.8337369 | M24: 137.6 | N24: =((M24-M12)/M12)*100 -> 4.8780488
A25: Rural+Urban | B25: 2017 | C25: December | D25: 12 | E25: 1949.2 | F25: =((E25-E13)/E13)*100 -> 3.4717061 | G25: 1087.6 | H25: =((G25-G13)/G13)*100 -> 5.0922794 | I25: 259.6 | J25: =((I25-I13)/I13)*100 -> 4.6774194 | K25: 257.6 | L25: =((K25-K13)/K13)*100 -> 3.8291012 | M25: 137.2 | N25: =((M25-M13)/M13)*100 -> 5.2147239
... A89: Rural+Urban | B89: 2023 | C89: May | D89: 5 | E89: 2507.9 | F89: =((E89-E77)/E77)*100 -> 3.0785039 | G89: 1428.7 | H89: =((G89-G77)/G77)*100 -> 5.2992335 | I89: 370.9 | J89: =((I89-I77)/I77)*100 -> 8.0710956 | K89: 346.9 | L89: =((K89-K77)/K77)*100 -> 4.2994588 | M89: 179.1 | N89: =((M89-M77)/M77)*100 -> 4.3098427

Sheet Que2 Inflamation
A1: Sector | B1: Year | C1: Month | D1: Index | E1: Food and Beverages Inflamation | F1: Essential Inflamation | G1: Healthcare Inflamation | H1: Miscellaneous Inflamation | I1: General CPI Inflamation
A2: Rural+Urban | B2: 2017 | C2: January | D2: 1 | E2: 2.419399 | F2: 4.6242192 | G2: 5.2008457 | H2: 4.3222828 | I2: 3.1670625
A3: Rural+Urban | B3: 2017 | C3: February | D3: 2 | E3: 2.9051819 | F3: 4.5035105 | G3: 4.558762 | H3: 4.1771094 | I3: 3.6507937
A4: Rural+Urban | B4: 2017 | C4: March | D4: 3 | E4: 2.8867914 | F4: 4.7991183 | G4: 4.2464613 | H4: 4.2517716 | I4: 3.8888889
A5: Rural+Urban | B5: 2017 | C5: April | D5: 4 | E5: 1.3816362 | F5: 4.6588188 | G5: 4.1027766 | H5: 3.7743675 | I5: 2.9850746
A6: Rural+Urban | B6: 2017 | C6: May | D6: 5 | E6: -0.12311975 | F6: 4.4018283 | G6: 3.4993825 | H6: 3.6333609 | I6: 2.1772939
A7: Rural+Urban | B7: 2017 | C7: June | D7: 6 | E7: -0.95298268 | F7: 3.9359177 | G7: 3.449692 | H7: 3.3717105 | I7: 1.4604151
A8: Rural+Urban | B8: 2017 | C8: July | D8: 7 | E8: -0.27043894 | F8: 4.0583136 | G8: 3.2653061 | H8: 3.3565289 | I8: 2.3646072
A9: Rural+Urban | B9: 2017 | C9: August | D9: 8 | E9: 0.80809134 | F9: 4.506185 | G9: 3.410475 | H9: 3.7990196 | I9: 3.279939
A10: Rural+Urban | B10: 2017 | C10: September | D10: 9 | E10: 0.84527747 | F10: 4.6138807 | G10: 3.5555556 | H10: 3.9479039 | I10: 3.2849503
A11: Rural+Urban | B11: 2017 | C11: October | D11: 10 | E11: 1.1893535 | F11: 4.6298998 | G11: 3.7469782 | H11: 3.7262049 | I11: 3.5768645
A12: Rural+Urban | B12: 2017 | C12: November | D12: 11 | E12: 3.1338732 | F12: 5.1876273 | G12: 4.1767068 | H12: 3.8337369 | I12: 4.8780488
A13: Rural+Urban | B13: 2017 | C13: December | D13: 12 | E13: 3.4717061 | F13: 5.0922794 | G13: 4.6774194 | H13: 3.8291012 | I13: 5.2147239
... A77: Rural+Urban | B77: 2023 | C77: May | D77: 5 | E77: 3.0785039 | F77: 5.2992335 | G77: 8.0710956 | H77: 4.2994588 | I77: 4.3098427

Sheet Que2 Analysis
A3: Year | B3: Index | C3: Month | D3: Average of Food and Beverages Inflamation | F3: Year | G3: Index | H3: Month | I3: Average of Essential Inflamation | K3: Year | L3: Index | M3: Month | N3: Average of Healthcare Inflamation | P3: Year | Q3: Index | R3: Month | S3: Average of Miscellaneous Inflamation | U3: Year | V3: Index | W3: Month | X3: Average of General CPI Inflamation
A4: 2017 | B4: 1 | C4: January | D4: 2.419399 | F4: 2017 | G4: 1 | H4: January | I4: 4.6242192 | K4: 2017 | L4: 1 | M4: January | N4: 5.2008457 | P4: 2017 | Q4: 1 | R4: January | S4: 4.3222828 | U4: 2017 | V4: 1 | W4: January | X4: 3.1670625
B5: 2 | C5: February | D5: 2.9051819 | G5: 2 | H5: February | I5: 4.5035105 | L5: 2 | M5: February | N5: 4.558762 | Q5: 2 | R5: February | S5: 4.1771094 | V5: 2 | W5: February | X5: 3.6507937
B6: 3 | C6: March | D6: 2.8867914 | G6: 3 | H6: March | I6: 4.7991183 | L6: 3 | M6: March | N6: 4.2464613 | Q6: 3 | R6: March | S6: 4.2517716 | V6: 3 | W6: March | X6: 3.8888889
B7: 4 | C7: April | D7: 1.3816362 | G7: 4 | H7: April | I7: 4.6588188 | L7: 4 | M7: April | N7: 4.1027766 | Q7: 4 | R7: April | S7: 3.7743675 | V7: 4 | W7: April | X7: 2.9850746
B8: 5 | C8: May | D8: -0.12311975 | G8: 5 | H8: May | I8: 4.4018283 | L8: 5 | M8: May | N8: 3.4993825 | Q8: 5 | R8: May | S8: 3.6333609 | V8: 5 | W8: May | X8: 2.1772939
B9: 6 | C9: June | D9: -0.95298268 | G9: 6 | H9: June | I9: 3.9359177 | L9: 6 | M9: June | N9: 3.449692 | Q9: 6 | R9: June | S9: 3.3717105 | V9: 6 | W9: June | X9: 1.4604151
B10: 7 | C10: July | D10: -0.27043894 | G10: 7 | H10: July | I10: 4.0583136 | L10: 7 | M10: July | N10: 3.2653061 | Q10: 7 | R10: July | S10: 3.3565289 | V10: 7 | W10: July | X10: 2.3646072
B11: 8 | C11: August | D11: 0.80809134 | G11: 8 | H11: August | I11: 4.506185 | L11: 8 | M11: August | N11: 3.410475 | Q11: 8 | R11: August | S11: 3.7990196 | V11: 8 | W11: August | X11: 3.279939
B12: 9 | C12: September | D12: 0.84527747 | G12: 9 | H12: September | I12: 4.6138807 | L12: 9 | M12: September | N12: 3.5555556 | Q12: 9 | R12: September | S12: 3.9479039 | V12: 9 | W12: September | X12: 3.2849503
